{"trial_id": "00", "hyperparameters": {"space": [{"class_name": "Choice", "config": {"name": "activation", "default": "LeakyReLU", "conditions": [], "values": ["LeakyReLU", "gelu", "relu"], "ordered": false}}, {"class_name": "Int", "config": {"name": "layer_1", "default": null, "conditions": [], "min_value": 1, "max_value": 512, "step": 16, "sampling": "linear"}}, {"class_name": "Int", "config": {"name": "layer_2", "default": null, "conditions": [], "min_value": 1, "max_value": 512, "step": 16, "sampling": "linear"}}, {"class_name": "Choice", "config": {"name": "learning_rate", "default": 0.01, "conditions": [], "values": [0.01, 0.001, 0.0001, 5e-05], "ordered": true}}], "values": {"activation": "LeakyReLU", "layer_1": 241, "layer_2": 81, "learning_rate": 0.001}}, "metrics": {"metrics": {}}, "score": null, "best_step": 0, "status": "FAILED", "message": "Traceback (most recent call last):\n  File \"C:\\Users\\jonat\\AppData\\Roaming\\Python\\Python310\\site-packages\\keras_tuner\\src\\engine\\base_tuner.py\", line 274, in _try_run_and_update_trial\n    self._run_and_update_trial(trial, *fit_args, **fit_kwargs)\n  File \"C:\\Users\\jonat\\AppData\\Roaming\\Python\\Python310\\site-packages\\keras_tuner\\src\\engine\\base_tuner.py\", line 239, in _run_and_update_trial\n    results = self.run_trial(trial, *fit_args, **fit_kwargs)\n  File \"C:\\Users\\jonat\\AppData\\Roaming\\Python\\Python310\\site-packages\\keras_tuner\\src\\engine\\tuner.py\", line 314, in run_trial\n    obj_value = self._build_and_fit_model(trial, *args, **copied_kwargs)\n  File \"C:\\Users\\jonat\\AppData\\Roaming\\Python\\Python310\\site-packages\\keras_tuner\\src\\engine\\tuner.py\", line 233, in _build_and_fit_model\n    results = self.hypermodel.fit(hp, model, *args, **kwargs)\n  File \"C:\\Users\\jonat\\AppData\\Roaming\\Python\\Python310\\site-packages\\keras_tuner\\src\\engine\\hypermodel.py\", line 149, in fit\n    return model.fit(*args, **kwargs)\n  File \"C:\\Users\\jonat\\AppData\\Roaming\\Python\\Python310\\site-packages\\keras\\src\\utils\\traceback_utils.py\", line 70, in error_handler\n    raise e.with_traceback(filtered_tb) from None\n  File \"C:\\Users\\jonat\\AppData\\Local\\Temp\\__autograph_generated_fileufho6qdl.py\", line 15, in tf__train_function\n    retval_ = ag__.converted_call(ag__.ld(step_function), (ag__.ld(self), ag__.ld(iterator)), None, fscope)\nValueError: in user code:\n\n    File \"C:\\Users\\jonat\\AppData\\Roaming\\Python\\Python310\\site-packages\\keras\\src\\engine\\training.py\", line 1377, in train_function  *\n        return step_function(self, iterator)\n    File \"C:\\Users\\jonat\\AppData\\Roaming\\Python\\Python310\\site-packages\\keras\\src\\engine\\training.py\", line 1360, in step_function  **\n        outputs = model.distribute_strategy.run(run_step, args=(data,))\n    File \"C:\\Users\\jonat\\AppData\\Roaming\\Python\\Python310\\site-packages\\keras\\src\\engine\\training.py\", line 1349, in run_step  **\n        outputs = model.train_step(data)\n    File \"C:\\Users\\jonat\\AppData\\Roaming\\Python\\Python310\\site-packages\\keras\\src\\engine\\training.py\", line 1126, in train_step\n        y_pred = self(x, training=True)\n    File \"C:\\Users\\jonat\\AppData\\Roaming\\Python\\Python310\\site-packages\\keras\\src\\utils\\traceback_utils.py\", line 70, in error_handler\n        raise e.with_traceback(filtered_tb) from None\n\n    ValueError: Exception encountered when calling layer 'conv1d_1' (type Conv1D).\n    \n    Negative dimension size caused by subtracting 3 from 1 for '{{node sequential/conv1d_1/Conv1D/Conv2D}} = Conv2D[T=DT_FLOAT, data_format=\"NHWC\", dilations=[1, 1, 1, 1], explicit_paddings=[], padding=\"VALID\", strides=[1, 1, 1, 1], use_cudnn_on_gpu=true](sequential/conv1d_1/Conv1D/Reshape, sequential/conv1d_1/Conv1D/ExpandDims_1)' with input shapes: [?,1,1,241], [1,3,241,81].\n    \n    Call arguments received by layer 'conv1d_1' (type Conv1D):\n      \u2022 inputs=tf.Tensor(shape=(None, 47, 1, 241), dtype=float32)\n\n"}